Workbook

Sheet ISIAN
K1: DATA ISIAN - isi kotak yang berwarna kuning saja
L2: (DI ISI KOLOM YANG BERWARNA KUNING SAJA)
K3: Kode Pemasaran | L3: 9495
K4: Nomor Covernote | L4: .../CN/VII/2026
K5: Nama Bank | L5: PT. Bank Mandiri KCP …
K6: Nama Tertanggung | L6: TBA
K7: Alamat Bank | L7: TBA
K8: Periode Awal | L8: 46283
K9: Periode Akhir | L9: 48109
A10: Kode | B10: OKUPASI | C10: Kode | D10: Rate | G10: Deductible
A11: 0 | B11: - | C11: - | D11: 0 | E11: 0 | F11: 0 | G11: - | K11: Alamat Risiko satu | L11: Kp. Lio RT.06 RW.01 Kel. Cipamokolan Kec. Rancasari Kota Bandung
A12: 1 | B12: BENGKEL LAS | C12: 2915 | D12: 2.263 | E12: 3.394 | F12: 4.526 | G12: 0.1% of TSI or 5% of Claim whichever higher | K12: Kode Okupasi | L12: 13 | M12: =VLOOKUP(L12,A11:C36,3,C11:C36) -> 2976 | N12: =IF(L13=1,VLOOKUP(L12,A11:D36,4,D11:D36),IF(L13=2,VLOOKUP(L12,A11:E36,5,D11:D36),VLOOKUP(L12,A11:F36,6,D11:D36))) -> 0.294 | O12: =VLOOKUP(L12,A11:G36,7,D11:D36) -> NILL | P12: =VLOOKUP(L12,A11:G36,2,D11:D36) -> RUMAH TINGGAL
A13: 2 | B13: APOTIK | C13: 2930 | D13: 0.889 | E13: 1.334 | F13: 1.778 | G13: 0.1% of TSI or 5% of Claim whichever higher | K13: Kelas Konstruksi | L13: 1
A14: 3 | B14: CONVENIENCE STORE/WARUNG KELONTONG | C14: 2933 | D14: 2.474 | E14: 3.711 | F14: 4.948 | G14: 0.1% of TSI or 5% of Claim whichever higher | K14: Penggunaan bangunan | L14: Bangunan tempat tinggal sekaligus tempat usaha
A15: 4 | B15: RUKO/SHOP/TOKO | C15: 2934 | D15: 1.52 | E15: 2.28 | F15: 3.04 | G15: NILL | K15: harga pertanggungan | L15: 110000000
A16: 5 | B16: RESTAURANT | C16: 2945 | D16: 1.479 | E16: 2.218 | F16: 2.958 | G16: 0.1% of TSI or 5% of Claim whichever higher
A17: 6 | B17: WARUNG MAKAN/KEDAI | C17: 2946 | D17: 2.278 | E17: 3.418 | F17: 4.557 | G17: 0.1% of TSI or 5% of Claim whichever higher | K17: Alamat Risiko Dua
A18: 7 | B18: SALON | C18: 2947 | D18: 0.781 | E18: 1.171 | F18: 1.562 | G18: 0.1% of TSI or 5% of Claim whichever higher | K18: Kode Okupasi | M18: =VLOOKUP(L18,A11:C36,3,C11:C36) -> - | N18: =IF(L19=1,VLOOKUP(L18,A11:D36,4,D11:D36),IF(L19=2,VLOOKUP(L18,A11:E36,5,D11:D36),VLOOKUP(L18,A11:F36,6,D11:D36))) -> 0 | O18: =VLOOKUP(L18,A11:G36,7,D11:D36) -> - | P18: =VLOOKUP(L18,A11:G36,2,D11:D36) -> -
A19: 8 | B19: HOSPITAL / KLINIK | C19: 2951 | D19: 0.378 | E19: 0.51 | F19: 0.642 | G19: 0.1% of TSI or 5% of Claim whichever higher | K19: Kelas Konstruksi
A20: 9 | B20: KANTOR/APARTEMEN < 6 LANTAI | C20: 2971 | D20: 0.368 | E20: 0.497 | F20: 0.625 | G20: NILL | K20: Penggunaan bangunan
A21: 10 | B21: KANTOR/APARTEMEN > 6 - 18 | C21: 2972 | D21: 0.385 | E21: 0.52 | F21: 0.655 | G21: 0.1% of TSI or 5% of Claim whichever higher | K21: harga pertanggungan
A22: 11 | B22: KANTOR/APARTEMEN > 18 - 24 | C22: 2973 | D22: 0.376 | E22: 0.507 | F22: 0.639 | G22: 0.1% of TSI or 5% of Claim whichever higher
A23: 12 | B23: KANTOR/APARTEMEN > 24 | C23: 2975 | D23: 0.455 | E23: 0.614 | F23: 0.774 | G23: 0.1% of TSI or 5% of Claim whichever higher | K23: Alamat Risiko Tiga
A24: 13 | B24: RUMAH TINGGAL | C24: 2976 | D24: 0.294 | E24: 0.397 | F24: 0.499 | G24: NILL | K24: Kode Okupasi | M24: =VLOOKUP(L24,A11:C36,3,C11:C36) -> - | N24: =IF(L25=1,VLOOKUP(L24,A11:D36,4,D11:D36),IF(L25=2,VLOOKUP(L24,A11:E36,5,D11:D36),VLOOKUP(L24,A11:F36,6,D11:D36))) -> 0 | O24: =VLOOKUP(L24,A11:G36,7,D11:D36) -> - | P24: =VLOOKUP(L24,A11:G36,2,D11:D36) -> -
A25: 14 | B25: KOS-KOSAN | C25: 29761 | D25: 0.478 | E25: 0.645 | F25: 0.812 | G25: NILL | K25: Kelas Konstruksi
A26: 15 | B26: SHOPPING MALL GRADE B | C26: 29313 | D26: 2.234 | E26: 3.35 | F26: 4.467 | G26: 0.1% of TSI or 5% of Claim whichever higher | K26: Penggunaan bangunan
A27: 16 | B27: GUDANG PRIBADI | C27: 29371 | D27: 1.127 | E27: 1.691 | F27: 2.255 | G27: 0.1% of TSI or 5% of Claim whichever higher | K27: harga pertanggungan
A28: 17 | B28: SHOWROOM ONLY | C28: 29395 | D28: 1.52 | E28: 2.28 | F28: 3.04 | G28: 0.1% of TSI or 5% of Claim whichever higher
A29: 18 | B29: PABRIK PEMBUATAN MAKANAN RINGAN | C29: 2723 | D29: 1.345 | E29: 2.018 | F29: 2.691 | G29: 0.1% of TSI or 5% of Claim whichever higher | K29: dibuat tanggal | L29: 44772
A30: 19 | B30: GARMENT ATAU KONVEKSI | C30: 2465 | D30: 1.906 | E30: 2.859 | F30: 3.812 | G30: 0.1% of TSI or 5% of Claim whichever higher | K30: Nama Kacab | L30: Hadi Kristianto
A31: 20 | B31: OTHER FARM | C31: 2735 | D31: 0.937 | E31: 1.406 | F31: 1.875 | G31: 0.1% of TSI or 5% of Claim whichever higher
A32: 21 | B32: KEDAI | C32: 2946 | D32: 2.278 | E32: 3.418 | F32: 4.557 | G32: 0.1% of TSI or 5% of Claim whichever higher | K32: isian lainnya
A33: 22 | B33: LAUNDRIES AND PRESSERS | C33: 2491 | D33: 2.8 | E33: 4.2 | F33: 6 | G33: 0.1% of TSI or 5% of Claim whichever higher
A34: 23 | B34: POULTRY FARMS | C34: 2734 | D34: 1.48 | E34: 2.221 | F34: 2.961 | G34: 0.1% of TSI or 5% of Claim whichever higher
A35: 24 | B35: CEMENT, CHALK, LIME AND GYPSYM INDUSTRY | C35: 2113 | D35: 0.69 | E35: 1.035 | G35: 0.1% of TSI or 5% of Claim whichever higher
A36: 25 | B36: Soya bean, tomato and hot pepper sauce | C36: 2733 | D36: 0.465 | E36: 0.698 | F36: 0.931 | G36: 0.1% of TSI or 5% of Claim whichever higher

Sheet HASIL
A1: COVER NOTE
A2: =ISIAN!L3 -> 9495
A3: Nomor Covernote | G3: : | H3: =ISIAN!L4 -> .../CN/VII/2026
A4: Nama Tertanggung | G4: : | H4: =ISIAN!L5 -> PT. Bank Mandiri KCP … | P4: QQ | Q4: =ISIAN!L6 -> TBA
A5: Alamat Tertanggung | G5: : | H5: =ISIAN!L7 -> TBA
A7: Lokasi Objek Pertanggungan | G7: : | H7: ="1."& " " &ISIAN!L11 -> 1. Kp. Lio RT.06 RW.01 Kel. Cipamokolan Kec. Rancasari Kota Bandung
H9: ="2."& " " &ISIAN!L17 -> 2.
H11: ="3."& " " &ISIAN!L23 -> 3.
A13: Jangka Waktu Pertanggungan | G13: : | H13: Mulai dari tanggal | L13: =ISIAN!L8 -> 46283 | O13: sampai dengan tanggal | Q13: =ISIAN!L9 -> 48109
H14: (kedua tanggal tersebut pada pukul 12.00 siang waktu setempat dimana harta benda
H15: yang dipertanggungkan berada)
A17: Okupasi : | L17: Kode Okupasi : | R17: Kelas Konstruksi :
A18: ="1."& " " &ISIAN!P12 -> 1. RUMAH TINGGAL | L18: =ISIAN!M12 -> 2976 | R18: =ISIAN!L13 -> 1
A20: ="2."& " " &ISIAN!P18 -> 2. - | L20: =ISIAN!M18 -> - | R20: =ISIAN!L19 -> 0
A22: ="3."& " " &ISIAN!P24 -> 3. - | L22: =ISIAN!M24 -> - | R22: =ISIAN!L25 -> 0
A24: Endorsement / Klausula / Syarat Tambahan :
B25: - klausula Perselisihan | N25: - Communicable Disease Exclusion - LMA 5393
B26: - klausula Kewajiban Pembayaran Premi
B27: - Warranty okupasi disekitar premises yang berdampingan rate tidak lebih besar
B28: - klausula Bank : | F28: =H4 -> PT. Bank Mandiri KCP …
A31: Risiko Sendiri
B32: ="1."& " " &"FLEXAS : "&ISIAN!O12 -> 1. FLEXAS : NILL
B33: ="2."& " " &"FLEXAS : "&ISIAN!O18 -> 2. FLEXAS : -
B34: ="3."& " " &"FLEXAS : "&ISIAN!O24 -> 3. FLEXAS : -
A36: No. | B36: Harta Benda dan atau kepentingan yang dipertanggungkan | R36: Harga pertanggungan
A37: 1 | B37: =ISIAN!L14 -> Bangunan tempat tinggal sekaligus tempat usaha | R37: IDR. | S37: =ISIAN!L15 -> 110000000
A39: 2 | B39: =ISIAN!L20 -> 0 | R39: IDR. | S39: =ISIAN!L21 -> 0
A41: 3 | B41: =ISIAN!L26 -> 0 | R41: IDR. | S41: =ISIAN!L27 -> 0
P43: Total | R43: IDR. | S43: =SUM(S37+S39+S41) -> 110000000
A45: Jaminan | L45: Suku Premi | R45: Premi
A46: 1. Pokok
B47: 1. FLEXAS | L47: =ISIAN!N12 -> 0.294 | N47: %o | R47: IDR. | S47: =(((ISIAN!L9-ISIAN!L8)/365)*((ISIAN!L15*ISIAN!N12)/1000)) -> 161788.6
B48: 2. FLEXAS | L48: =ISIAN!N18 -> 0 | N48: %o | R48: IDR. | S48: =(((ISIAN!L9-ISIAN!L8)/365)*((ISIAN!L21*ISIAN!N18)/1000)) -> 0
B49: 3. FLEXAS | L49: =ISIAN!N24 -> 0 | N49: %o | R49: IDR. | S49: =(((ISIAN!L9-ISIAN!L8)/365)*((ISIAN!L27*ISIAN!N24)/1000)) -> 0
L51: Sub Total | R51: IDR. | S51: =S47+S48+S49 -> 161788.6
L52: Biaya Polis | R52: IDR. | S52: 25000
L53: Biaya Materai | R53: IDR. | S53: =IF(S51>=5000000,20000,10000) -> 10000
L55: Total | R55: IDR. | S55: =SUM(S51:V54) -> 196788.6
P58: Dibuat di, Bandung
P59: pada tanggal, | S59: =ISIAN!L29 -> 44772
...

Sheet BUAT SPPA
A2: =ISIAN!L3 -> 9495
A3: Nama Tertanggung | G3: : | H3: =ISIAN!L5 -> PT. Bank Mandiri KCP … | P3: QQ | Q3: =ISIAN!L6 -> TBA
A4: Alamat Tertanggung | G4: : | H4: =ISIAN!L7 -> TBA
A6: Lokasi Objek Pertanggungan | G6: : | H6: ="1."& " " &ISIAN!L11 -> 1. Kp. Lio RT.06 RW.01 Kel. Cipamokolan Kec. Rancasari Kota Bandung
H8: ="2."& " " &ISIAN!L17 -> 2.
H10: ="3."& " " &ISIAN!L23 -> 3.
A12: Jangka Waktu Pertanggungan | G12: : | H12: Mulai dari tanggal | L12: =ISIAN!L8 -> 46283 | O12: sampai dengan tanggal | Q12: =ISIAN!L9 -> 48109
A14: Okupasi : | L14: Kode Okupasi : | R14: Kelas Konstruksi :
A15: ="1."& " " &ISIAN!P12 -> 1. RUMAH TINGGAL | L15: =ISIAN!M12 -> 2976 | R15: =ISIAN!L13 -> 1
A17: ="2."& " " &ISIAN!P18 -> 2. - | L17: =ISIAN!M18 -> - | R17: =ISIAN!L19 -> 0
A19: ="3."& " " &ISIAN!P24 -> 3. - | L19: =ISIAN!M24 -> - | R19: =ISIAN!L25 -> 0
A21: No. | B21: Harta Benda dan atau kepentingan yang dipertanggungkan | R21: Harga pertanggungan
A22: 1 | B22: =ISIAN!L14 -> Bangunan tempat tinggal sekaligus tempat usaha | R22: IDR. | S22: =ISIAN!L15 -> 110000000
A24: 2 | B24: =ISIAN!L20 -> 0 | R24: IDR. | S24: =ISIAN!L21 -> 0
A26: 3 | B26: =ISIAN!L26 -> 0 | R26: IDR. | S26: =ISIAN!L27 -> 0
P28: Total | R28: IDR. | S28: =SUM(S22+S24+S26) -> 110000000
A30: Jaminan | L30: Suku Premi | R30: Premi
A31: 1. Pokok
B32: 1. FLEXAS | L32: =ISIAN!N12 -> 0.294 | N32: %o | R32: IDR. | S32: =(((ISIAN!L9-ISIAN!L8)/365)*((ISIAN!L15*ISIAN!N12)/1000)) -> 161788.6
B33: 2. FLEXAS | L33: =ISIAN!N18 -> 0 | N33: %o | R33: IDR. | S33: =(((ISIAN!L9-ISIAN!L8)/365)*((ISIAN!L21*ISIAN!N18)/1000)) -> 0
B34: 3. FLEXAS | L34: =ISIAN!N24 -> 0 | N34: %o | R34: IDR. | S34: =(((ISIAN!L9-ISIAN!L8)/365)*((ISIAN!L27*ISIAN!N24)/1000)) -> 0
L36: Sub Total | R36: IDR. | S36: =S32+S33+S34 -> 161788.6
L37: Biaya Polis | R37: IDR. | S37: 25000
L38: Biaya Materai | R38: IDR. | S38: =IF(S36>=5000000,20000,10000) -> 10000
L40: Total | R40: IDR. | S40: =SUM(S36:V39) -> 196788.6
